2018-08-14T20:35:39.888332+00:00 app[web.1]:   File "/app/.heroku/python/lib/python2.7/site-packages/django/contrib/auth/views.py", line 90, in dispatch
2018-08-14T20:35:39.888334+00:00 app[web.1]:     return super(LoginView, self).dispatch(request, *args, **kwargs)
2018-08-14T20:35:39.888335+00:00 app[web.1]:   File "/app/.heroku/python/lib/python2.7/site-packages/django/views/generic/base.py", line 88, in dispatch
2018-08-14T20:35:39.888337+00:00 app[web.1]:     return handler(request, *args, **kwargs)
2018-08-14T20:35:39.888338+00:00 app[web.1]:   File "/app/.heroku/python/lib/python2.7/site-packages/django/views/generic/edit.py", line 174, in get
2018-08-14T20:35:39.888340+00:00 app[web.1]:     return self.render_to_response(self.get_context_data())
2018-08-14T20:35:39.888341+00:00 app[web.1]:   File "/app/.heroku/python/lib/python2.7/site-packages/django/contrib/auth/views.py", line 124, in get_context_data
2018-08-14T20:35:39.888343+00:00 app[web.1]:     current_site = get_current_site(self.request)
2018-08-14T20:35:39.888345+00:00 app[web.1]:   File "/app/.heroku/python/lib/python2.7/site-packages/django/contrib/sites/shortcuts.py", line 15, in get_current_site
2018-08-14T20:35:39.888346+00:00 app[web.1]:     return Site.objects.get_current(request)
2018-08-14T20:35:39.888348+00:00 app[web.1]:   File "/app/.heroku/python/lib/python2.7/site-packages/django/contrib/sites/models.py", line 63, in get_current
2018-08-14T20:35:39.888349+00:00 app[web.1]:     return self._get_site_by_id(site_id)
2018-08-14T20:35:39.888351+00:00 app[web.1]:   File "/app/.heroku/python/lib/python2.7/site-packages/django/contrib/sites/models.py", line 35, in _get_site_by_id
2018-08-14T20:35:39.888352+00:00 app[web.1]:     site = self.get(pk=site_id)
2018-08-14T20:35:39.888354+00:00 app[web.1]:   File "/app/.heroku/python/lib/python2.7/site-packages/django/db/models/manager.py", line 85, in manager_method
2018-08-14T20:35:39.888355+00:00 app[web.1]:     return getattr(self.get_queryset(), name)(*args, **kwargs)
2018-08-14T20:35:39.888357+00:00 app[web.1]:   File "/app/.heroku/python/lib/python2.7/site-packages/django/db/models/query.py", line 374, in get
2018-08-14T20:35:39.888359+00:00 app[web.1]:     num = len(clone)
2018-08-14T20:35:39.888360+00:00 app[web.1]:   File "/app/.heroku/python/lib/python2.7/site-packages/django/db/models/query.py", line 232, in __len__
2018-08-14T20:35:39.888362+00:00 app[web.1]:     self._fetch_all()
2018-08-14T20:35:39.888372+00:00 app[web.1]:   File "/app/.heroku/python/lib/python2.7/site-packages/django/db/models/query.py", line 1118, in _fetch_all
2018-08-14T20:35:39.888373+00:00 app[web.1]:     self._result_cache = list(self._iterable_class(self))
2018-08-14T20:35:39.888375+00:00 app[web.1]:   File "/app/.heroku/python/lib/python2.7/site-packages/django/db/models/query.py", line 53, in __iter__
2018-08-14T20:35:39.888377+00:00 app[web.1]:     results = compiler.execute_sql(chunked_fetch=self.chunked_fetch)
2018-08-14T20:35:39.888378+00:00 app[web.1]:   File "/app/.heroku/python/lib/python2.7/site-packages/django/db/models/sql/compiler.py", line 899, in execute_sql
2018-08-14T20:35:39.888380+00:00 app[web.1]:     raise original_exception
2018-08-14T20:35:39.888381+00:00 app[web.1]: ProgrammingError: relation "django_site" does not exist
2018-08-14T20:35:39.888382+00:00 app[web.1]: LINE 1: ..."django_site"."domain", "django_site"."name" FROM "django_si...
2018-08-14T20:35:39.888384+00:00 app[web.1]:                                                              ^
2018-08-14T20:35:39.888386+00:00 app[web.1]: 
2018-08-14T20:35:40.029233+00:00 app[web.1]: 10.37.182.119 - - [14/Aug/2018:20:35:40 +0000] "GET /login/ HTTP/1.1" 500 169939 "-" "Mozilla/5.0 (Windows NT 6.3; Win64; x64; rv:59.0) Gecko/20100101 Firefox/59.0"
2018-08-14T20:35:40.038934+00:00 heroku[router]: at=info method=GET path="/login/" host=evotche.herokuapp.com request_id=93ff8a53-e8e1-44d9-9220-e11797cb7684 fwd="196.220.66.2" dyno=web.1 connect=1ms service=542ms status=500 bytes=170150 protocol=http
2018-08-14T20:35:43.146572+00:00 app[web.1]: Internal Server Error: /favicon.ico
2018-08-14T20:35:43.146584+00:00 app[web.1]: Traceback (most recent call last):
2018-08-14T20:35:43.146586+00:00 app[web.1]:   File "/app/.heroku/python/lib/python2.7/site-packages/django/core/handlers/exception.py", line 41, in inner
2018-08-14T20:35:43.146588+00:00 app[web.1]:     response = get_response(request)
2018-08-14T20:35:43.146590+00:00 app[web.1]:   File "/app/.heroku/python/lib/python2.7/site-packages/django/core/handlers/base.py", line 187, in _get_response
2018-08-14T20:35:43.146592+00:00 app[web.1]:     response = self.process_exception_by_middleware(e, request)
2018-08-14T20:35:43.146594+00:00 app[web.1]:   File "/app/.heroku/python/lib/python2.7/site-packages/django/core/handlers/base.py", line 185, in _get_response
2018-08-14T20:35:43.146612+00:00 app[web.1]:     response = wrapped_callback(request, *callback_args, **callback_kwargs)
2018-08-14T20:35:43.146619+00:00 app[web.1]:   File "/app/.heroku/python/lib/python2.7/site-packages/django/contrib/flatpages/views.py", line 35, in flatpage
2018-08-14T20:35:43.146621+00:00 app[web.1]:     site_id = get_current_site(request).id
2018-08-14T20:35:43.146623+00:00 app[web.1]:   File "/app/.heroku/python/lib/python2.7/site-packages/django/contrib/sites/shortcuts.py", line 15, in get_current_site
2018-08-14T20:35:43.146624+00:00 app[web.1]:     return Site.objects.get_current(request)
2018-08-14T20:35:43.146626+00:00 app[web.1]:   File "/app/.heroku/python/lib/python2.7/site-packages/django/contrib/sites/models.py", line 63, in get_current
2018-08-14T20:35:43.146628+00:00 app[web.1]:     return self._get_site_by_id(site_id)
2018-08-14T20:35:43.146629+00:00 app[web.1]:   File "/app/.heroku/python/lib/python2.7/site-packages/django/contrib/sites/models.py", line 35, in _get_site_by_id
2018-08-14T20:35:43.146632+00:00 app[web.1]:     site = self.get(pk=site_id)
2018-08-14T20:35:43.146633+00:00 app[web.1]:   File "/app/.heroku/python/lib/python2.7/site-packages/django/db/models/manager.py", line 85, in manager_method
2018-08-14T20:35:43.146635+00:00 app[web.1]:     return getattr(self.get_queryset(), name)(*args, **kwargs)
2018-08-14T20:35:43.146636+00:00 app[web.1]:   File "/app/.heroku/python/lib/python2.7/site-packages/django/db/models/query.py", line 374, in get
2018-08-14T20:35:43.146638+00:00 app[web.1]:     num = len(clone)
2018-08-14T20:35:43.146640+00:00 app[web.1]:   File "/app/.heroku/python/lib/python2.7/site-packages/django/db/models/query.py", line 232, in __len__
2018-08-14T20:35:43.146641+00:00 app[web.1]:     self._fetch_all()
2018-08-14T20:35:43.146643+00:00 app[web.1]:   File "/app/.heroku/python/lib/python2.7/site-packages/django/db/models/query.py", line 1118, in _fetch_all
2018-08-14T20:35:43.146645+00:00 app[web.1]:     self._result_cache = list(self._iterable_class(self))
2018-08-14T20:35:43.146646+00:00 app[web.1]:   File "/app/.heroku/python/lib/python2.7/site-packages/django/db/models/query.py", line 53, in __iter__
2018-08-14T20:35:43.146648+00:00 app[web.1]:     results = compiler.execute_sql(chunked_fetch=self.chunked_fetch)
2018-08-14T20:35:43.146650+00:00 app[web.1]:   File "/app/.heroku/python/lib/python2.7/site-packages/django/db/models/sql/compiler.py", line 899, in execute_sql
2018-08-14T20:35:43.146652+00:00 app[web.1]:     raise original_exception
2018-08-14T20:35:43.146653+00:00 app[web.1]: ProgrammingError: relation "django_site" does not exist
2018-08-14T20:35:43.146655+00:00 app[web.1]: LINE 1: ..."django_site"."domain", "django_site"."name" FROM "django_si...
2018-08-14T20:35:43.146657+00:00 app[web.1]:                                                              ^
2018-08-14T20:35:43.146658+00:00 app[web.1]: 
2018-08-14T20:35:43.337060+00:00 app[web.1]: 10.67.229.158 - - [14/Aug/2018:20:35:43 +0000] "GET /favicon.ico HTTP/1.1" 500 101764 "-" "Mozilla/5.0 (Windows NT 6.3; Win64; x64; rv:59.0) Gecko/20100101 Firefox/59.0"
2018-08-14T20:35:43.341979+00:00 heroku[router]: at=info method=GET path="/favicon.ico" host=evotche.herokuapp.com request_id=a1633a1b-e20d-4dd8-b7d6-03096b3db23d fwd="196.220.66.2" dyno=web.1 connect=0ms service=436ms status=500 bytes=101975 protocol=http
2018-08-14T20:35:43.705765+00:00 app[web.1]: Internal Server Error: /favicon.ico
2018-08-14T20:35:43.705771+00:00 app[web.1]: Traceback (most recent call last):
2018-08-14T20:35:43.705773+00:00 app[web.1]:   File "/app/.heroku/python/lib/python2.7/site-packages/django/core/handlers/exception.py", line 41, in inner
2018-08-14T20:35:43.705775+00:00 app[web.1]:     response = get_response(request)
2018-08-14T20:35:43.705777+00:00 app[web.1]:   File "/app/.heroku/python/lib/python2.7/site-packages/django/core/handlers/base.py", line 187, in _get_response
2018-08-14T20:35:43.705779+00:00 app[web.1]:     response = self.process_exception_by_middleware(e, request)
2018-08-14T20:35:43.705781+00:00 app[web.1]:   File "/app/.heroku/python/lib/python2.7/site-packages/django/core/handlers/base.py", line 185, in _get_response
2018-08-14T20:35:43.705783+00:00 app[web.1]:     response = wrapped_callback(request, *callback_args, **callback_kwargs)
2018-08-14T20:35:43.705785+00:00 app[web.1]:   File "/app/.heroku/python/lib/python2.7/site-packages/django/contrib/flatpages/views.py", line 35, in flatpage
2018-08-14T20:35:43.705795+00:00 app[web.1]:     site_id = get_current_site(request).id
2018-08-14T20:35:43.705797+00:00 app[web.1]:   File "/app/.heroku/python/lib/python2.7/site-packages/django/contrib/sites/shortcuts.py", line 15, in get_current_site
2018-08-14T20:35:43.705798+00:00 app[web.1]:     return Site.objects.get_current(request)
2018-08-14T20:35:43.705800+00:00 app[web.1]:   File "/app/.heroku/python/lib/python2.7/site-packages/django/contrib/sites/models.py", line 63, in get_current
2018-08-14T20:35:43.705802+00:00 app[web.1]:     return self._get_site_by_id(site_id)
2018-08-14T20:35:43.705806+00:00 app[web.1]:   File "/app/.heroku/python/lib/python2.7/site-packages/django/contrib/sites/models.py", line 35, in _get_site_by_id
2018-08-14T20:35:43.705808+00:00 app[web.1]:     site = self.get(pk=site_id)
2018-08-14T20:35:43.705812+00:00 app[web.1]:     return getattr(self.get_queryset(), name)(*args, **kwargs)
2018-08-14T20:35:43.705815+00:00 app[web.1]:     num = len(clone)
2018-08-14T20:35:43.705810+00:00 app[web.1]:   File "/app/.heroku/python/lib/python2.7/site-packages/django/db/models/manager.py", line 85, in manager_method
2018-08-14T20:35:43.705813+00:00 app[web.1]:   File "/app/.heroku/python/lib/python2.7/site-packages/django/db/models/query.py", line 374, in get
2018-08-14T20:35:43.705816+00:00 app[web.1]:   File "/app/.heroku/python/lib/python2.7/site-packages/django/db/models/query.py", line 232, in __len__
2018-08-14T20:35:43.705818+00:00 app[web.1]:     self._fetch_all()
2018-08-14T20:35:43.705821+00:00 app[web.1]:     self._result_cache = list(self._iterable_class(self))
2018-08-14T20:35:43.705820+00:00 app[web.1]:   File "/app/.heroku/python/lib/python2.7/site-packages/django/db/models/query.py", line 1118, in _fetch_all
2018-08-14T20:35:43.705824+00:00 app[web.1]:     results = compiler.execute_sql(chunked_fetch=self.chunked_fetch)
2018-08-14T20:35:43.705826+00:00 app[web.1]:   File "/app/.heroku/python/lib/python2.7/site-packages/django/db/models/sql/compiler.py", line 899, in execute_sql
2018-08-14T20:35:43.705828+00:00 app[web.1]:     raise original_exception
2018-08-14T20:35:43.705829+00:00 app[web.1]: ProgrammingError: relation "django_site" does not exist
2018-08-14T20:35:43.705831+00:00 app[web.1]: LINE 1: ..."django_site"."domain", "django_site"."name" FROM "django_si...
2018-08-14T20:35:43.705833+00:00 app[web.1]:                                                              ^
2018-08-14T20:35:43.705835+00:00 app[web.1]: 
2018-08-14T20:35:43.872999+00:00 app[web.1]: 10.37.182.119 - - [14/Aug/2018:20:35:43 +0000] "GET /favicon.ico HTTP/1.1" 500 101824 "-" "Mozilla/5.0 (Windows NT 6.3; Win64; x64; rv:59.0) Gecko/20100101 Firefox/59.0"
2018-08-14T20:35:43.705823+00:00 app[web.1]:   File "/app/.heroku/python/lib/python2.7/site-packages/django/db/models/query.py", line 53, in __iter__
2018-08-14T20:35:43.879670+00:00 heroku[router]: at=info method=GET path="/favicon.ico" host=evotche.herokuapp.com request_id=fb7be2ef-83e8-4c6d-8475-17a3e3428adb fwd="196.220.66.2" dyno=web.1 connect=1ms service=189ms status=500 bytes=102035 protocol=http
